<?xml version="1.0" ?>
<robot name="Assm" xmlns:xacro="http://www.ros.org/wiki/xacro">

<xacro:include filename="$(find Assm_description)/urdf/materials.xacro" />
<xacro:include filename="$(find Assm_description)/urdf/Assm.ros2control" />
<xacro:include filename="$(find Assm_description)/urdf/Assm.gazebo" />
<link name="base_link">
  <inertial>
    <origin xyz="0.005450285535566075 0.0028327915449261154 0.0011676081391321141" rpy="0 0 0"/>
    <mass value="0.3857637405193081"/>
    <inertia ixx="0.000383" iyy="0.000399" izz="0.000751" ixy="-1.5e-05" iyz="-1e-06" ixz="1e-06"/>
  </inertial>
  <visual>
    <origin xyz="0 0 0" rpy="0 0 0"/>
    <geometry>
      <mesh filename="file://$(find Assm_description)/meshes/base_link.stl" scale="0.001 0.001 0.001"/>
    </geometry>
    <material name="silver"/>
  </visual>
  <collision>
    <origin xyz="0 0 0" rpy="0 0 0"/>
    <geometry>
      <mesh filename="file://$(find Assm_description)/meshes/base_link.stl" scale="0.001 0.001 0.001"/>
    </geometry>
  </collision>
</link>

<link name="limb_2_1_3">
  <inertial>
    <origin xyz="-0.017939963784019828 0.026423584252083993 4.683265387196711e-07" rpy="0 0 0"/>
    <mass value="0.057466860924570075"/>
    <inertia ixx="1.5e-05" iyy="1.3e-05" izz="2.6e-05" ixy="0.0" iyz="-0.0" ixz="0.0"/>
  </inertial>
  <visual>
    <origin xyz="-0.003869 -0.063937 0.005719" rpy="0 0 0"/>
    <geometry>
      <mesh filename="file://$(find Assm_description)/meshes/limb_2_1_3.stl" scale="0.001 0.001 0.001"/>
    </geometry>
    <material name="silver"/>
  </visual>
  <collision>
    <origin xyz="-0.003869 -0.063937 0.005719" rpy="0 0 0"/>
    <geometry>
      <mesh filename="file://$(find Assm_description)/meshes/limb_2_1_3.stl" scale="0.001 0.001 0.001"/>
    </geometry>
  </collision>
</link>

<link name="limb_1_3_3">
  <inertial>
    <origin xyz="0.016568334427794235 0.000850356744703698 -0.013045734619034697" rpy="0 0 0"/>
    <mass value="0.10238612425988404"/>
    <inertia ixx="4.4e-05" iyy="4.5e-05" izz="6e-06" ixy="0.0" iyz="0.0" ixz="0.0"/>
  </inertial>
  <visual>
    <origin xyz="0.031631 -0.118937 0.005719" rpy="0 0 0"/>
    <geometry>
      <mesh filename="file://$(find Assm_description)/meshes/limb_1_3_3.stl" scale="0.001 0.001 0.001"/>
    </geometry>
    <material name="silver"/>
  </visual>
  <collision>
    <origin xyz="0.031631 -0.118937 0.005719" rpy="0 0 0"/>
    <geometry>
      <mesh filename="file://$(find Assm_description)/meshes/limb_1_3_3.stl" scale="0.001 0.001 0.001"/>
    </geometry>
  </collision>
</link>

<link name="limb_2_1_1">
  <inertial>
    <origin xyz="0.01794053600284727 -0.01787835604374112 -0.01945673024885675" rpy="0 0 0"/>
    <mass value="0.057466860924570075"/>
    <inertia ixx="1.5e-05" iyy="2e-05" izz="1.9e-05" ixy="0.0" iyz="-7e-06" ixz="0.0"/>
  </inertial>
  <visual>
    <origin xyz="-0.008449 0.059241 0.003557" rpy="0 0 0"/>
    <geometry>
      <mesh filename="file://$(find Assm_description)/meshes/limb_2_1_1.stl" scale="0.001 0.001 0.001"/>
    </geometry>
    <material name="silver"/>
  </visual>
  <collision>
    <origin xyz="-0.008449 0.059241 0.003557" rpy="0 0 0"/>
    <geometry>
      <mesh filename="file://$(find Assm_description)/meshes/limb_2_1_1.stl" scale="0.001 0.001 0.001"/>
    </geometry>
  </collision>
</link>

<link name="limb_1_3_1">
  <inertial>
    <origin xyz="-0.016567762208992986 0.004546209816010241 -0.012258496357176497" rpy="0 0 0"/>
    <mass value="0.10238612425988404"/>
    <inertia ixx="4.4e-05" iyy="3.9e-05" izz="1.2e-05" ixy="0.0" iyz="1.4e-05" ixz="0.0"/>
  </inertial>
  <visual>
    <origin xyz="-0.043949 0.096455 0.044055" rpy="0 0 0"/>
    <geometry>
      <mesh filename="file://$(find Assm_description)/meshes/limb_1_3_1.stl" scale="0.001 0.001 0.001"/>
    </geometry>
    <material name="silver"/>
  </visual>
  <collision>
    <origin xyz="-0.043949 0.096455 0.044055" rpy="0 0 0"/>
    <geometry>
      <mesh filename="file://$(find Assm_description)/meshes/limb_1_3_1.stl" scale="0.001 0.001 0.001"/>
    </geometry>
  </collision>
</link>

<link name="limb_2_1_2">
  <inertial>
    <origin xyz="0.014940421590430016 -0.021036197637545002 -0.01599010576032387" rpy="0 0 0"/>
    <mass value="0.057466860924570075"/>
    <inertia ixx="1.5e-05" iyy="1.8e-05" izz="2.1e-05" ixy="0.0" iyz="-6e-06" ixz="0.0"/>
  </inertial>
  <visual>
    <origin xyz="0.039389 0.058331 0.003068" rpy="0 0 0"/>
    <geometry>
      <mesh filename="file://$(find Assm_description)/meshes/limb_2_1_2.stl" scale="0.001 0.001 0.001"/>
    </geometry>
    <material name="silver"/>
  </visual>
  <collision>
    <origin xyz="0.039389 0.058331 0.003068" rpy="0 0 0"/>
    <geometry>
      <mesh filename="file://$(find Assm_description)/meshes/limb_2_1_2.stl" scale="0.001 0.001 0.001"/>
    </geometry>
  </collision>
</link>

<link name="limb_1_3_2">
  <inertial>
    <origin xyz="-0.016567876621383898 -0.010533117865850233 0.007744010163671957" rpy="0 0 0"/>
    <mass value="0.10238612425988404"/>
    <inertia ixx="4.4e-05" iyy="1.8e-05" izz="3.4e-05" ixy="-0.0" iyz="1.8e-05" ixz="-0.0"/>
  </inertial>
  <visual>
    <origin xyz="0.009889 0.102118 0.036351" rpy="0 0 0"/>
    <geometry>
      <mesh filename="file://$(find Assm_description)/meshes/limb_1_3_2.stl" scale="0.001 0.001 0.001"/>
    </geometry>
    <material name="silver"/>
  </visual>
  <collision>
    <origin xyz="0.009889 0.102118 0.036351" rpy="0 0 0"/>
    <geometry>
      <mesh filename="file://$(find Assm_description)/meshes/limb_1_3_2.stl" scale="0.001 0.001 0.001"/>
    </geometry>
  </collision>
</link>

<link name="limb_2_1_4">
  <inertial>
    <origin xyz="-0.014940377518736232 0.026423646856156266 -4.305966192674933e-07" rpy="0 0 0"/>
    <mass value="0.057466860924570075"/>
    <inertia ixx="1.5e-05" iyy="1.3e-05" izz="2.6e-05" ixy="0.0" iyz="-0.0" ixz="0.0"/>
  </inertial>
  <visual>
    <origin xyz="-0.060756 -0.065467 0.003377" rpy="0 0 0"/>
    <geometry>
      <mesh filename="file://$(find Assm_description)/meshes/limb_2_1_4.stl" scale="0.001 0.001 0.001"/>
    </geometry>
    <material name="silver"/>
  </visual>
  <collision>
    <origin xyz="-0.060756 -0.065467 0.003377" rpy="0 0 0"/>
    <geometry>
      <mesh filename="file://$(find Assm_description)/meshes/limb_2_1_4.stl" scale="0.001 0.001 0.001"/>
    </geometry>
  </collision>
</link>

<link name="limb_1_3_4">
  <inertial>
    <origin xyz="0.016567920693077623 0.01307413780451154 1.9095796676761242e-05" rpy="0 0 0"/>
    <mass value="0.10238612425988404"/>
    <inertia ixx="4.4e-05" iyy="6e-06" izz="4.5e-05" ixy="-0.0" iyz="2e-06" ixz="0.0"/>
  </inertial>
  <visual>
    <origin xyz="-0.031256 -0.120467 0.003377" rpy="0 0 0"/>
    <geometry>
      <mesh filename="file://$(find Assm_description)/meshes/limb_1_3_4.stl" scale="0.001 0.001 0.001"/>
    </geometry>
    <material name="silver"/>
  </visual>
  <collision>
    <origin xyz="-0.031256 -0.120467 0.003377" rpy="0 0 0"/>
    <geometry>
      <mesh filename="file://$(find Assm_description)/meshes/limb_1_3_4.stl" scale="0.001 0.001 0.001"/>
    </geometry>
  </collision>
</link>

<link name="limb_1_1_1">
  <inertial>
    <origin xyz="-0.002315327637535468 -0.024653738379607937 -0.014940106390473835" rpy="0 0 0"/>
    <mass value="0.0923182155552708"/>
    <inertia ixx="1.4e-05" iyy="1.2e-05" izz="1e-05" ixy="-1e-06" iyz="-0.0" ixz="-0.0"/>
  </inertial>
  <visual>
    <origin xyz="-0.028896 0.031658 -0.016594" rpy="0 0 0"/>
    <geometry>
      <mesh filename="file://$(find Assm_description)/meshes/limb_1_1_1.stl" scale="0.001 0.001 0.001"/>
    </geometry>
    <material name="silver"/>
  </visual>
  <collision>
    <origin xyz="-0.028896 0.031658 -0.016594" rpy="0 0 0"/>
    <geometry>
      <mesh filename="file://$(find Assm_description)/meshes/limb_1_1_1.stl" scale="0.001 0.001 0.001"/>
    </geometry>
  </collision>
</link>

<link name="limb_1_1_3">
  <inertial>
    <origin xyz="0.0023148998563176024 0.024654295925299996 -0.017790208656825818" rpy="0 0 0"/>
    <mass value="0.0923182155552708"/>
    <inertia ixx="1.4e-05" iyy="1.2e-05" izz="1e-05" ixy="-1e-06" iyz="0.0" ixz="0.0"/>
  </inertial>
  <visual>
    <origin xyz="0.016577 -0.036354 -0.017283" rpy="0 0 0"/>
    <geometry>
      <mesh filename="file://$(find Assm_description)/meshes/limb_1_1_3.stl" scale="0.001 0.001 0.001"/>
    </geometry>
    <material name="silver"/>
  </visual>
  <collision>
    <origin xyz="0.016577 -0.036354 -0.017283" rpy="0 0 0"/>
    <geometry>
      <mesh filename="file://$(find Assm_description)/meshes/limb_1_1_3.stl" scale="0.001 0.001 0.001"/>
    </geometry>
  </collision>
</link>

<link name="limb_1_1_4">
  <inertial>
    <origin xyz="0.002314486121601317 0.024654358529365344 -0.017790088860185568" rpy="0 0 0"/>
    <mass value="0.0923182155552708"/>
    <inertia ixx="1.4e-05" iyy="1.2e-05" izz="1e-05" ixy="-1e-06" iyz="0.0" ixz="0.0"/>
  </inertial>
  <visual>
    <origin xyz="-0.04316 -0.037884 -0.019624" rpy="0 0 0"/>
    <geometry>
      <mesh filename="file://$(find Assm_description)/meshes/limb_1_1_4.stl" scale="0.001 0.001 0.001"/>
    </geometry>
    <material name="silver"/>
  </visual>
  <collision>
    <origin xyz="-0.04316 -0.037884 -0.019624" rpy="0 0 0"/>
    <geometry>
      <mesh filename="file://$(find Assm_description)/meshes/limb_1_1_4.stl" scale="0.001 0.001 0.001"/>
    </geometry>
  </collision>
</link>

<link name="limb_1_1_2">
  <inertial>
    <origin xyz="-0.0023144420499072935 -0.024654186463004508 -0.017789845863430343" rpy="0 0 0"/>
    <mass value="0.0923182155552708"/>
    <inertia ixx="1.4e-05" iyy="1.2e-05" izz="1e-05" ixy="-1e-06" iyz="-0.0" ixz="-0.0"/>
  </inertial>
  <visual>
    <origin xyz="0.018943 0.030748 -0.019933" rpy="0 0 0"/>
    <geometry>
      <mesh filename="file://$(find Assm_description)/meshes/limb_1_1_2.stl" scale="0.001 0.001 0.001"/>
    </geometry>
    <material name="silver"/>
  </visual>
  <collision>
    <origin xyz="0.018943 0.030748 -0.019933" rpy="0 0 0"/>
    <geometry>
      <mesh filename="file://$(find Assm_description)/meshes/limb_1_1_2.stl" scale="0.001 0.001 0.001"/>
    </geometry>
  </collision>
</link>

<joint name="Revolute 23" type="continuous">
  <origin xyz="0.020446 0.027583 -0.023002" rpy="0 0 0"/>
  <parent link="limb_1_1_3"/>
  <child link="limb_2_1_3"/>
  <axis xyz="1.0 0.0 -0.0"/>
</joint>

<joint name="Revolute 24" type="continuous">
  <origin xyz="-0.0355 0.055 0.0" rpy="0 0 0"/>
  <parent link="limb_2_1_3"/>
  <child link="limb_1_3_3"/>
  <axis xyz="-1.0 -0.0 0.0"/>
</joint>

<joint name="Revolute 26" type="continuous">
  <origin xyz="-0.020447 -0.027583 -0.020151" rpy="0 0 0"/>
  <parent link="limb_1_1_1"/>
  <child link="limb_2_1_1"/>
  <axis xyz="-1.0 -0.0 -0.0"/>
</joint>

<joint name="Revolute 27" type="continuous">
  <origin xyz="0.0355 -0.037214 -0.040498" rpy="0 0 0"/>
  <parent link="limb_2_1_1"/>
  <child link="limb_1_3_1"/>
  <axis xyz="1.0 0.0 0.0"/>
</joint>

<joint name="Revolute 29" type="continuous">
  <origin xyz="-0.020446 -0.027583 -0.023001" rpy="0 0 0"/>
  <parent link="limb_1_1_2"/>
  <child link="limb_2_1_2"/>
  <axis xyz="-1.0 -0.0 0.0"/>
</joint>

<joint name="Revolute 30" type="continuous">
  <origin xyz="0.0295 -0.043787 -0.033283" rpy="0 0 0"/>
  <parent link="limb_2_1_2"/>
  <child link="limb_1_3_2"/>
  <axis xyz="1.0 0.0 -0.0"/>
</joint>

<joint name="Revolute 36" type="continuous">
  <origin xyz="0.017596 0.027583 -0.023001" rpy="0 0 0"/>
  <parent link="limb_1_1_4"/>
  <child link="limb_2_1_4"/>
  <axis xyz="1.0 0.0 -0.0"/>
</joint>

<joint name="Revolute 37" type="continuous">
  <origin xyz="-0.0295 0.055 0.0" rpy="0 0 0"/>
  <parent link="limb_2_1_4"/>
  <child link="limb_1_3_4"/>
  <axis xyz="-1.0 -0.0 0.0"/>
</joint>

<joint name="Revolute 38" type="continuous">
  <origin xyz="0.028896 -0.031658 0.016594" rpy="0 0 0"/>
  <parent link="base_link"/>
  <child link="limb_1_1_1"/>
  <axis xyz="-0.0 0.0 1.0"/>
</joint>

<joint name="Revolute 39" type="continuous">
  <origin xyz="-0.016577 0.036354 0.017283" rpy="0 0 0"/>
  <parent link="base_link"/>
  <child link="limb_1_1_3"/>
  <axis xyz="0.0 -0.0 1.0"/>
</joint>

<joint name="Revolute 40" type="continuous">
  <origin xyz="0.04316 0.037884 0.019624" rpy="0 0 0"/>
  <parent link="base_link"/>
  <child link="limb_1_1_4"/>
  <axis xyz="0.0 -0.0 1.0"/>
</joint>

<joint name="Revolute 41" type="continuous">
  <origin xyz="-0.018943 -0.030748 0.019933" rpy="0 0 0"/>
  <parent link="base_link"/>
  <child link="limb_1_1_2"/>
  <axis xyz="0.0 0.0 1.0"/>
</joint>

</robot>
