<?xml version="1.0" ?>
<robot name="Assm" xmlns:xacro="http://www.ros.org/wiki/xacro">

<xacro:include filename="$(find Assm_description)/urdf/materials.xacro" />
<xacro:include filename="$(find Assm_description)/urdf/Assm.ros2control" />
<xacro:include filename="$(find Assm_description)/urdf/Assm.gazebo" />

<link name="base_link">
  <inertial>
    <origin xyz="0.005450285535566075 0.0028327915449261154 0.0011676081391321141" rpy="0 0 0"/>
    <mass value="0.3857637405193081"/>
    <inertia ixx="0.04766" iyy="0.05193" izz="0.09567" ixy="0.0" iyz="0.0" ixz="0.0"/>
  </inertial>
  <visual>
    <origin xyz="0 0 0" rpy="0 0 0"/>
    <geometry>
      <mesh filename="file://$(find Assm_description)/meshes/base_link.stl" scale="0.001 0.001 0.001"/>
    </geometry>
    <material name="silver"/>
  </visual>
  <collision>
    <origin xyz="0 0 0" rpy="0 0 0"/>
    <geometry>
      <mesh filename="file://$(find Assm_description)/meshes/base_link.stl" scale="0.001 0.001 0.001"/>
    </geometry>
  </collision>
</link>

<link name="imu_link">
    <inertial>
        <mass value="0.001"/> 
        <inertia ixx="0.000001" ixy="0.0" ixz="0.0" iyy="0.000001" iyz="0.0" izz="0.000001"/>
    </inertial>
    <visual>
        <geometry>
            <box size="0.001 0.001 0.001"/>
        </geometry>
    </visual>
</link>

<joint name="imu_joint" type="fixed">
    <parent link="base_link"/>
    <child link="imu_link"/>
    <origin xyz="0 0 0.01" rpy="0 0 0"/> 
</joint>

<link name="limb_1_1_1">
  <inertial>
    <origin xyz="-0.002315327637535468 -0.024653738379607937 -0.014940106390473835" rpy="0 0 0"/>
    <mass value="0.0923182155552708"/>
    <inertia ixx="0.00125" iyy="0.00146" izz="0.00177" ixy="0.0" iyz="0.0" ixz="0.0"/>
  </inertial>
  <visual>
    <origin xyz="-0.028896 0.031658 -0.016594" rpy="0 0 0"/>
    <geometry>
      <mesh filename="file://$(find Assm_description)/meshes/limb_1_1_1.stl" scale="0.001 0.001 0.001"/>
    </geometry>
    <material name="green"/>
  </visual>
  <collision>
    <origin xyz="-0.028896 0.031658 -0.016594" rpy="0 0 0"/>
    <geometry>
      <mesh filename="file://$(find Assm_description)/meshes/limb_1_1_1.stl" scale="0.001 0.001 0.001"/>
    </geometry>
  </collision>
</link>

<link name="limb_1_1_2">
  <inertial>
    <origin xyz="-0.0023144420499072935 -0.024654186463004508 -0.017789845863430343" rpy="0 0 0"/>
    <mass value="0.0923182155552708"/>
    <inertia ixx="0.00125" iyy="0.00146" izz="0.00177" ixy="0.0" iyz="0.0" ixz="0.0"/>
  </inertial>
  <visual>
    <origin xyz="0.018943 0.030748 -0.019933" rpy="0 0 0"/>
    <geometry>
      <mesh filename="file://$(find Assm_description)/meshes/limb_1_1_2.stl" scale="0.001 0.001 0.001"/>
    </geometry>
    <material name="blue"/>
  </visual>
  <collision>
    <origin xyz="0.018943 0.030748 -0.019933" rpy="0 0 0"/>
    <geometry>
      <mesh filename="file://$(find Assm_description)/meshes/limb_1_1_2.stl" scale="0.001 0.001 0.001"/>
    </geometry>
  </collision>
</link>

<link name="limb_1_1_3">
  <inertial>
    <origin xyz="0.0023148998563176024 0.024654295925299996 -0.017790208656825818" rpy="0 0 0"/>
    <mass value="0.0923182155552708"/>
    <inertia ixx="0.00125" iyy="0.00146" izz="0.00177" ixy="0.0" iyz="0.0" ixz="0.0"/>
  </inertial>
  <visual>
    <origin xyz="0.016577 -0.036354 -0.017283" rpy="0 0 0"/>
    <geometry>
      <mesh filename="file://$(find Assm_description)/meshes/limb_1_1_3.stl" scale="0.001 0.001 0.001"/>
    </geometry>
    <material name="yellow"/>
  </visual>
  <collision>
    <origin xyz="0.016577 -0.036354 -0.017283" rpy="0 0 0"/>
    <geometry>
      <mesh filename="file://$(find Assm_description)/meshes/limb_1_1_3.stl" scale="0.001 0.001 0.001"/>
    </geometry>
  </collision>
</link>

<link name="limb_1_1_4">
  <inertial>
    <origin xyz="0.002314486121601317 0.024654358529365344 -0.017790088860185568" rpy="0 0 0"/>
    <mass value="0.0923182155552708"/>
    <inertia ixx="0.00125" iyy="0.00146" izz="0.00177" ixy="0.0" iyz="0.0" ixz="0.0"/>
  </inertial>
  <visual>
    <origin xyz="-0.04316 -0.037884 -0.019624" rpy="0 0 0"/>
    <geometry>
      <mesh filename="file://$(find Assm_description)/meshes/limb_1_1_4.stl" scale="0.001 0.001 0.001"/>
    </geometry>
    <material name="silver"/>
  </visual>
  <collision>
    <origin xyz="-0.04316 -0.037884 -0.019624" rpy="0 0 0"/>
    <geometry>
      <mesh filename="file://$(find Assm_description)/meshes/limb_1_1_4.stl" scale="0.001 0.001 0.001"/>
    </geometry>
  </collision>
</link>

<link name="limb_2_1_1">
  <inertial>
    <origin xyz="0.01794053600284727 -0.01787835604374112 -0.01945673024885675" rpy="0 0 0"/>
    <mass value="0.057466860924570075"/>
    <inertia ixx="0.00166" iyy="0.00185" izz="0.00333" ixy="0.0" iyz="0.0" ixz="0.0"/>
  </inertial>
  <visual>
    <origin xyz="-0.008449 0.059241 0.003557" rpy="0 0 0"/>
    <geometry>
      <mesh filename="file://$(find Assm_description)/meshes/limb_2_1_1.stl" scale="0.001 0.001 0.001"/>
    </geometry>
    <material name="silver"/>
  </visual>
  <collision>
    <origin xyz="-0.008449 0.059241 0.003557" rpy="0 0 0"/>
    <geometry>
      <mesh filename="file://$(find Assm_description)/meshes/limb_2_1_1.stl" scale="0.001 0.001 0.001"/>
    </geometry>
  </collision>
</link>

<link name="limb_2_1_2">
  <inertial>
    <origin xyz="0.014940421590430016 -0.021036197637545002 -0.01599010576032387" rpy="0 0 0"/>
    <mass value="0.057466860924570075"/>
    <inertia ixx="0.00166" iyy="0.00185" izz="0.00333" ixy="0.0" iyz="0.0" ixz="0.0"/>
  </inertial>
  <visual>
    <origin xyz="0.039389 0.058331 0.003068" rpy="0 0 0"/>
    <geometry>
      <mesh filename="file://$(find Assm_description)/meshes/limb_2_1_2.stl" scale="0.001 0.001 0.001"/>
    </geometry>
    <material name="silver"/>
  </visual>
  <collision>
    <origin xyz="0.039389 0.058331 0.003068" rpy="0 0 0"/>
    <geometry>
      <mesh filename="file://$(find Assm_description)/meshes/limb_2_1_2.stl" scale="0.001 0.001 0.001"/>
    </geometry>
  </collision>
</link>

<link name="limb_2_1_3">
  <inertial>
    <origin xyz="-0.017939963784019828 0.026423584252083993 4.683265387196711e-07" rpy="0 0 0"/>
    <mass value="0.057466860924570075"/>
    <inertia ixx="0.00166" iyy="0.00185" izz="0.00333" ixy="0.0" iyz="0.0" ixz="0.0"/>
  </inertial>
  <visual>
    <origin xyz="-0.003869 -0.063937 0.005719" rpy="0 0 0"/>
    <geometry>
      <mesh filename="file://$(find Assm_description)/meshes/limb_2_1_3.stl" scale="0.001 0.001 0.001"/>
    </geometry>
    <material name="silver"/>
  </visual>
  <collision>
    <origin xyz="-0.003869 -0.063937 0.005719" rpy="0 0 0"/>
    <geometry>
      <mesh filename="file://$(find Assm_description)/meshes/limb_2_1_3.stl" scale="0.001 0.001 0.001"/>
    </geometry>
  </collision>
</link>

<link name="limb_2_1_4">
  <inertial>
    <origin xyz="-0.014940377518736232 0.026423646856156266 -4.305966192674933e-07" rpy="0 0 0"/>
    <mass value="0.057466860924570075"/>
    <inertia ixx="0.00166" iyy="0.00185" izz="0.00333" ixy="0.0" iyz="0.0" ixz="0.0"/>
  </inertial>
  <visual>
    <origin xyz="-0.060756 -0.065467 0.003377" rpy="0 0 0"/>
    <geometry>
      <mesh filename="file://$(find Assm_description)/meshes/limb_2_1_4.stl" scale="0.001 0.001 0.001"/>
    </geometry>
    <material name="silver"/>
  </visual>
  <collision>
    <origin xyz="-0.060756 -0.065467 0.003377" rpy="0 0 0"/>
    <geometry>
      <mesh filename="file://$(find Assm_description)/meshes/limb_2_1_4.stl" scale="0.001 0.001 0.001"/>
    </geometry>
  </collision>
</link>

<link name="limb_1_3_1">
  <inertial>
    <origin xyz="-0.016567762208992986 0.004546209816010241 -0.012258496357176497" rpy="0 0 0"/>
    <mass value="0.10238612425988404"/>
    <inertia ixx="0.00077" iyy="0.00556" izz="0.00579" ixy="0.0" iyz="0.0" ixz="0.0"/>
  </inertial>
  <visual>
    <origin xyz="-0.043949 0.096455 0.044055" rpy="0 0 0"/>
    <geometry>
      <mesh filename="file://$(find Assm_description)/meshes/limb_1_3_1.stl" scale="0.001 0.001 0.001"/>
    </geometry>
    <material name="silver"/>
  </visual>
  <collision>
    <origin xyz="-0.043949 0.096455 0.044055" rpy="0 0 0"/>
    <geometry>
      <mesh filename="file://$(find Assm_description)/meshes/limb_1_3_1.stl" scale="0.001 0.001 0.001"/>
    </geometry>
  </collision>
</link>

<link name="limb_1_3_2">
  <inertial>
    <origin xyz="-0.016567876621383898 -0.010533117865850233 0.007744010163671957" rpy="0 0 0"/>
    <mass value="0.10238612425988404"/>
    <inertia ixx="0.00077" iyy="0.00556" izz="0.00579" ixy="0.0" iyz="0.0" ixz="0.0"/>
  </inertial>
  <visual>
    <origin xyz="0.009889 0.102118 0.036351" rpy="0 0 0"/>
    <geometry>
      <mesh filename="file://$(find Assm_description)/meshes/limb_1_3_2.stl" scale="0.001 0.001 0.001"/>
    </geometry>
    <material name="silver"/>
  </visual>
  <collision>
    <origin xyz="0.009889 0.102118 0.036351" rpy="0 0 0"/>
    <geometry>
      <mesh filename="file://$(find Assm_description)/meshes/limb_1_3_2.stl" scale="0.001 0.001 0.001"/>
    </geometry>
  </collision>
</link>

<link name="limb_1_3_3">
  <inertial>
    <origin xyz="0.016568334427794235 0.000850356744703698 -0.013045734619034697" rpy="0 0 0"/>
    <mass value="0.10238612425988404"/>
    <inertia ixx="0.00077" iyy="0.00556" izz="0.00579" ixy="0.0" iyz="0.0" ixz="0.0"/>
  </inertial>
  <visual>
    <origin xyz="0.031631 -0.118937 0.005719" rpy="0 0 0"/>
    <geometry>
      <mesh filename="file://$(find Assm_description)/meshes/limb_1_3_3.stl" scale="0.001 0.001 0.001"/>
    </geometry>
    <material name="silver"/>
  </visual>
  <collision>
    <origin xyz="0.031631 -0.118937 0.005719" rpy="0 0 0"/>
    <geometry>
      <mesh filename="file://$(find Assm_description)/meshes/limb_1_3_3.stl" scale="0.001 0.001 0.001"/>
    </geometry>
  </collision>
</link>

<link name="limb_1_3_4">
  <inertial>
    <origin xyz="0.016567920693077623 0.01307413780451154 1.9095796676761242e-05" rpy="0 0 0"/>
    <mass value="0.10238612425988404"/>
    <inertia ixx="0.00077" iyy="0.00556" izz="0.00579" ixy="0.0" iyz="0.0" ixz="0.0"/>
  </inertial>
  <visual>
    <origin xyz="-0.031256 -0.120467 0.003377" rpy="0 0 0"/>
    <geometry>
      <mesh filename="file://$(find Assm_description)/meshes/limb_1_3_4.stl" scale="0.001 0.001 0.001"/>
    </geometry>
    <material name="silver"/>
  </visual>
  <collision>
    <origin xyz="-0.031256 -0.120467 0.003377" rpy="0 0 0"/>
    <geometry>
      <mesh filename="file://$(find Assm_description)/meshes/limb_1_3_4.stl" scale="0.001 0.001 0.001"/>
    </geometry>
  </collision>
</link>

<joint name="Revolute_Coxa_1" type="revolute">
  <origin xyz="-0.018943 -0.030748 0.019933" rpy="0 0 0"/>
  <parent link="base_link"/>
  <child link="limb_1_1_2"/>
  <axis xyz="0.0 0.0 1.0"/>
  <limit lower="-1.57" upper="1.57" effort="10.0" velocity="5.0"/>
  <dynamics damping="1.0" friction="0.2"/>
  <param name="initial_position">0.00</param>
</joint>

<joint name="Revolute_Coxa_2" type="revolute">
  <origin xyz="-0.016577 0.036354 0.017283" rpy="0 0 0"/>
  <parent link="base_link"/>
  <child link="limb_1_1_3"/>
  <axis xyz="0.0 -0.0 1.0"/>
  <limit lower="-1.57" upper="1.57" effort="10.0" velocity="5.0"/>
  <dynamics damping="1.0" friction="0.2"/>
  <param name="initial_position">0.00</param>
</joint>

<joint name="Revolute_Coxa_3" type="revolute">
  <origin xyz="0.028896 -0.031658 0.016594" rpy="0 0 0"/>
  <parent link="base_link"/>
  <child link="limb_1_1_1"/>
  <axis xyz="-0.0 0.0 1.0"/>
  <limit lower="-1.57" upper="1.57" effort="10.0" velocity="5.0"/>
  <dynamics damping="1.0" friction="0.2"/>
  <param name="initial_position">0.00</param>
</joint>

<joint name="Revolute_Coxa_4" type="revolute">
  <origin xyz="0.04316 0.037884 0.019624" rpy="0 0 0"/>
  <parent link="base_link"/>
  <child link="limb_1_1_4"/>
  <axis xyz="0.0 -0.0 1.0"/>
  <limit lower="-1.57" upper="1.57" effort="10.0" velocity="5.0"/>
  <dynamics damping="1.0" friction="0.2"/>
  <param name="initial_position">0.00</param>
</joint>

<joint name="Revolute_Femur_1" type="revolute">
  <origin xyz="-0.020446 -0.027583 -0.023001" rpy="0 0 0"/>
  <parent link="limb_1_1_2"/>
  <child link="limb_2_1_2"/>
  <axis xyz="-1.0 -0.0 0.0"/>
  <limit lower="-1.6" upper="1.6" effort="10.0" velocity="5.0"/>
  <dynamics damping="1.0" friction="0.2"/>
  <param name="initial_position">0.62</param>
</joint>

<joint name="Revolute_Femur_2" type="revolute">
  <origin xyz="0.020446 0.027583 -0.023002" rpy="0 0 0"/>
  <parent link="limb_1_1_3"/>
  <child link="limb_2_1_3"/>
  <axis xyz="1.0 0.0 -0.0"/>
  <limit lower="-1.6" upper="1.6" effort="10.0" velocity="5.0"/>
  <dynamics damping="1.0" friction="0.2"/>
  <param name="initial_position">0.00</param>
</joint>

<joint name="Revolute_Femur_3" type="revolute">
  <origin xyz="-0.020447 -0.027583 -0.023001" rpy="0 0 0"/>
  <parent link="limb_1_1_1"/>
  <child link="limb_2_1_1"/>
  <axis xyz="-1.0 -0.0 -0.0"/>
  <limit lower="-1.6" upper="1.6" effort="10.0" velocity="5.0"/>
  <dynamics damping="1.0" friction="0.2"/>
  <param name="initial_position">0.83</param>
</joint>

<joint name="Revolute_Femur_4" type="revolute">
  <origin xyz="0.020447 0.027583 -0.023001" rpy="0 0 0"/>
  <parent link="limb_1_1_4"/>
  <child link="limb_2_1_4"/>
  <axis xyz="1.0 0.0 -0.0"/>
  <limit lower="-1.6" upper="1.6" effort="10.0" velocity="5.0"/>
  <dynamics damping="1.0" friction="0.2"/>
  <param name="initial_position">0.00</param>
</joint>

<joint name="Revolute_Tibia_1" type="revolute">
  <origin xyz="0.0295 -0.043787 -0.033283" rpy="0 0 0"/>
  <parent link="limb_2_1_2"/>
  <child link="limb_1_3_2"/>
  <axis xyz="1.0 0.0 -0.0"/>
  <limit lower="-10.0" upper="10.0" effort="10.0" velocity="5.0"/>
  <dynamics damping="1.0" friction="0.2"/>
  <param name="initial_position">2.80</param>
</joint>

<joint name="Revolute_Tibia_2" type="revolute">
  <origin xyz="-0.0355 0.055 0.0" rpy="0 0 0"/>
  <parent link="limb_2_1_3"/>
  <child link="limb_1_3_3"/>
  <axis xyz="-1.0 -0.0 0.0"/>
  <limit lower="-2.0" upper="2.0" effort="10.0" velocity="5.0"/>
  <dynamics damping="1.0" friction="0.2"/>
  <param name="initial_position">0.00</param>
</joint>

<joint name="Revolute_Tibia_3" type="revolute">
  <origin xyz="0.0355 -0.037214 -0.040498" rpy="0 0 0"/>
  <parent link="limb_2_1_1"/>
  <child link="limb_1_3_1"/>
  <axis xyz="1.0 0.0 0.0"/>
  <limit lower="-2.0" upper="2.0" effort="10.0" velocity="5.0"/>
  <dynamics damping="1.0" friction="0.2"/>
  <param name="initial_position">0.45</param>
</joint>

<joint name="Revolute_Tibia_4" type="revolute">
  <origin xyz="-0.0295 0.055 0.0" rpy="0 0 0"/>
  <parent link="limb_2_1_4"/>
  <child link="limb_1_3_4"/>
  <axis xyz="-1.0 -0.0 0.0"/>
  <limit lower="-2.0" upper="2.0" effort="10.0" velocity="5.0"/>
  <dynamics damping="1.0" friction="0.2"/>
  <param name="initial_position">1.55</param>
</joint>


<gazebo>
  <plugin filename="libgazebo_ros2_control.so" name="gazebo_ros2_control">
    <parameters>$(find Assm_description)/config/ros_controller.yaml</parameters>
  </plugin>
</gazebo>

<gazebo reference="imu_link">
    <sensor name="imu_sensor" type="imu">
        <always_on>true</always_on>
        <update_rate>100.0</update_rate>
        <visualize>false</visualize>
        
        <plugin name="imu_plugin" filename="libgazebo_ros_imu_sensor.so">
            <ros>
                <namespace>/</namespace>
                <argument>imu/data</argument>
            </ros>
            <initial_orientation_as_reference>false</initial_orientation_as_reference>
        </plugin>
        
        <imu>
            <angular_velocity>
                <x>0.0002 0.0002 0.0002</x>
                <y>0.0002 0.0002 0.0002</y>
                <z>0.0002 0.0002 0.0002</z>
            </angular_velocity>
            <linear_acceleration>
                <x>0.002 0.002 0.002</x>
                <y>0.002 0.002 0.002</y>
                <z>0.002 0.002 0.002</z>
            </linear_acceleration>
        </imu>
    </sensor>
</gazebo>

</robot>